Workbook
Name Slicer_Department: #N/A
Name Slicer_Designation: #N/A
Name Slicer_Gender: #N/A
Name Slicer_Location: #N/A

Sheet row data
A1: Employee ID | B1: Employee Name | C1: Date of Birth | D1: Joining Date | E1: Department | F1: Salary | G1: Location | H1: Gender | I1: Job Code | J1: Designation | K1: Working Experience
A2: EMP1001 | B2: Anvi Rama | C2: 22180 | D2: 41839 | E2: Marketing | F2: 68714 | G2: Kolkata | H2: Female | I2: JC588 | J2: Consultant | K2: 11
A3: EMP1004 | B3: Zeeshan Bali | C3: 36636 | D3: 43163 | E3: HR | F3: 173501 | G3: Mumbai | H3: Female | I3: JC196 | J3: Assistant | K3: 7
A4: EMP1006 | B4: Akarsh Shanker | C4: 34522 | D4: 40325 | E4: Marketing | F4: 78659 | G4: Kolkata | H4: Male | I4: JC693 | J4: Lead | K4: 15
A5: EMP1007 | B5: Aaryahi Kaur | C5: 35976 | D5: 36810 | E5: Sales | F5: 122559 | G5: Ahmedabad | H5: Male | I5: JC100 | J5: Assistant | K5: 25
A6: EMP1008 | B6: Aaryahi Ray | C6: 22441 | D6: 31501 | E6: Support | F6: 143801 | G6: Ahmedabad | H6: Male | I6: JC598 | J6: Lead | K6: 39
A7: EMP1010 | B7: Sahil Khalsa | C7: 33598 | D7: 25818 | E7: HR | F7: 85405 | G7: Chennai | H7: Female | I7: JC877 | J7: Lead | K7: 55
A8: EMP1011 | C8: 29425 | D8: 36320 | E8: Operations | F8: 24858 | G8: Delhi | H8: Male | I8: JC894 | J8: Lead | K8: 26
A9: EMP1013 | B9: Shaan Mani | C9: 29059 | D9: 36818 | E9: Sales | F9: 182803 | G9: Pune | H9: Male | I9: JC303 | J9: Lead | K9: 25
A10: EMP1014 | B10: Yuvraj Rout | C10: 37619 | D10: 25882 | E10: Finance | F10: 127076 | G10: Pune | H10: Male | I10: JC710 | J10: Manager | K10: 55
A11: EMP1016 | B11: Anay Kothari | C11: 33969 | D11: 35916 | E11: Support | F11: 65259 | G11: Chennai | H11: Female | I11: JC991 | J11: Analyst | K11: 27
A12: EMP1017 | B12: Amani Manda | C12: 28579 | D12: 43735 | E12: IT | F12: 178832 | G12: Ahmedabad | H12: Male | I12: JC944 | J12: Lead | K12: 6
A13: EMP1019 | B13: Azad Trivedi | C13: 28684 | D13: 38675 | E13: IT | F13: 57911 | G13: Ahmedabad | H13: Female | I13: $JC767 | J13: Manager | K13: 20
A14: EMP1020 | B14: Kaira Shukla | C14: 33868 | D14: 37851 | E14: Operations | F14: 86201 | G14: Jaipur | H14: Female | I14: JC919 | J14: Assistant | K14: 22
A15: EMP1021 | B15: Khushi Viswanathan | C15: 35709 | D15: 36955 | E15: IT | F15: 116998 | G15: Mumbai | H15: Female | I15: JC351 | J15: Manager | K15: 24
A16: EMP1024 | B16: Hrishita Sachar | C16: 36838 | D16: 31253 | E16: Support | F16: 163291 | G16: Delhi | H16: Male | I16: JC669 | J16: Manager | K16: 40
A17: EMP1025 | B17: Kanav Kulkarni | C17: 29000 | D17: 36557 | E17: HR | F17: 80988 | G17: Pune | H17: Male | I17: JC738 | J17: Analyst | K17: 25
A18: EMP1026 | B18: Jivin Acharya | C18: 28243 | D18: 26438 | E18: Sales | F18: 140435 | H18: Pune | I18: Female | J18: JC992 | K18: Analyst | L18: 53
A19: EMP1027 | B19: Samiha Bansal | C19: 33113 | D19: 28588 | E19: HR | F19: 62510 | G19: Hyderabad | H19: Female | I19: JC987 | J19: Executive | K19: 47
A20: EMP1028 | B20: Divit Dixit | C20: 27985 | D20: 29873 | E20: IT | F20: 90827 | G20: Kolkata | H20: Female | I20: JC634 | J20: Manager | K20: 44
A21: EMP1029 | B21: Mishti Das | C21: 25861 | D21: 41187 | E21: IT | F21: 184057 | G21: Kolkata | H21: Male | I21: JC149 | J21: Manager | K21: 13
A22: EMP1032 | B22: Eshani Swamy | C22: 23674 | D22: 39722 | E22: Marketing | F22: 132823 | G22: Jaipur | H22: Male | I22: JC859 | J22: Assistant | K22: 17
A23: EMP1033 | B23: Rati Gulati | C23: 36398 | D23: 27440 | E23: Support | F23: 97382 | G23: Ahmedabad | H23: Female | I23: JC709 | J23: Manager | K23: 50
A24: EMP1036 | B24: Rohan Deol | C24: 33309 | D24: 39066 | E24: Operations | F24: 152798 | G24: Pune | H24: Male | I24: JC833 | J24: Executive | K24: 19
A25: EMP1037 | B25: Priyansh Deo | C25: 29157 | D25: 40324 | E25: HR | F25: 24173 | G25: Lucknow | H25: Female | I25: JC924 | J25: Lead | K25: 15
A26: EMP1038 | B26: Pranay Desai | C26: 35758 | D26: 30603 | E26: Sales | F26: 131132 | G26: Bangalore | H26: Male | I26: JC317 | J26: Lead | K26: 42
A27: EMP1039 | B27: Pari Butala | C27: 29646 | D27: 36278 | E27: Support | F27: 145437 | G27: Delhi | H27: Male | I27: JC976 | J27: Manager | K27: 26
A28: EMP1040 | B28: Damini Sunder | C28: 30828 | D28: 32530 | E28: Marketing | F28: 135145 | G28: Chennai | H28: Male | I28: JC753 | J28: Analyst | K28: 36
A29: EMP1041 | B29: Rasha Srinivasan | C29: 31291 | D29: 37094 | E29: Finance | F29: 87948 | G29: Bangalore | H29: Male | I29: JC965 | J29: Lead | K29: 24
A30: EMP1042 | B30: Baiju Buch | C30: 32183 | D30: 29739 | E30: Operations | F30: 144034 | G30: Kolkata | H30: Female | I30: JC600 | J30: Lead | K30: 44
... A37: EMP1049 | B37: Biju Rau | C37: 34500 | D37: 35659 | E37: Support | F37: 64595 | G37: Kolkata | H37: Male | I37: JC413 | J37: Manager | K37: 28
A38: EMP1050 | B38: Hridaan Seth | C38: 29077 | D38: 40509 | F38: 146314 | G38: Jaipur | H38: Male | I38: JC179 | J38: Lead | K38: 15
A39: EMP1051 | B39: Piya Kakar | C39: 36362 | D39: 37478 | E39: Sales | F39: 186139 | G39: Hyderabad | H39: Male | I39: JC286 | J39: Executive | K39: 23
A40: EMP1052 | B40: Mahika Mannan | C40: 31525 | D40: 38054 | E40: Operations | F40: 92655 | G40: Hyderabad | H40: Male | I40: JC711 | J40: Engineer | K40: 21
A41: EMP1054 | B41: Tushar Thaman | C41: 24005 | D41: 26505 | E41: IT | F41: 104585 | G41: Pune | H41: Male | I41: JC755 | J41: Manager | K41: 53
A42: EMP1055 | B42: Ela Comar | C42: 30768 | D42: 38661 | E42: Support | F42: 133053 | G42: Chennai | H42: Male | I42: JC861 | J42: Assistant | K42: 20
A43: EMP1057 | B43: Mehul Banerjee | C43: 35241 | D43: 29801 | E43: Marketing | F43: 155724 | G43: Kolkata | H43: Female | I43: JC117 | J43: Executive | K43: 44
A44: EMP1062 | B44: Hridaan Tank | C44: 31623 | D44: 26672 | E44: Marketing | F44: 71232 | G44: Mumbai | H44: Male | I44: JC218 | J44: Manager | K44: 52
A45: EMP1063 | B45: Taimur Sankaran | C45: 28482 | D45: 35206 | E45: Operations | F45: 23743 | G45: Lucknow | H45: Male | I45: JC646 | J45: Consultant | K45: 29
A46: EMP1065 | B46: Fateh Rana | C46: 27760 | D46: 37335 | E46: Finance | F46: 100175 | G46: Kolkata | H46: Male | I46: JC635 | J46: Analyst | K46: 23
...

Sheet  table formate
A1: Employee ID | B1: Length | C1: Employee Name | D1: Date of Birth | E1: Joining Date | F1: Department | G1: Salary | H1: Location | I1: Gender | J1: Job Code | K1: Designation | L1: Working Experience
A2: EMP1001 | B2: =LEN(Table2[[#This Row],[Employee ID]]) -> 7 | C2: Anvi Rama | D2: 22180 | E2: 41839 | F2: Marketing | G2: 68714 | H2: Kolkata | I2: Female | J2: JC588 | K2: Consultant | L2: 11
A3: EMP1004 | B3: =LEN(Table2[[#This Row],[Employee ID]]) -> 7 | C3: Zeeshan Bali | D3: 36636 | E3: 43163 | F3: HR | G3: 173501 | H3: Mumbai | I3: Female | J3: JC196 | K3: Assistant | L3: 7
A4: EMP1006 | B4: =LEN(Table2[[#This Row],[Employee ID]]) -> 7 | C4: Akarsh Shanker | D4: 34522 | E4: 40325 | F4: Marketing | G4: 78659 | H4: Kolkata | I4: Male | J4: JC693 | K4: Lead | L4: 15
A5: EMP1007 | B5: =LEN(Table2[[#This Row],[Employee ID]]) -> 7 | C5: Aaryahi Kaur | D5: 35976 | E5: 36810 | F5: Sales | G5: 122559 | H5: Ahmedabad | I5: Male | J5: JC100 | K5: Assistant | L5: 25
A6: EMP1008 | B6: =LEN(Table2[[#This Row],[Employee ID]]) -> 7 | C6: Aaryahi Ray | D6: 22441 | E6: 31501 | F6: Support | G6: 143801 | H6: Ahmedabad | I6: Male | J6: JC598 | K6: Lead | L6: 39
A7: EMP1010 | B7: =LEN(Table2[[#This Row],[Employee ID]]) -> 7 | C7: Sahil Khalsa | D7: 33598 | E7: 25818 | F7: HR | G7: 85405 | H7: Chennai | I7: Female | J7: JC877 | K7: Lead | L7: 55
A8: EMP1011 | B8: =LEN(Table2[[#This Row],[Employee ID]]) -> 7 | C8: Shaan Mani | D8: 29425 | E8: 36320 | F8: Operations | G8: 24858 | H8: Delhi | I8: Male | J8: JC894 | K8: Lead | L8: 26
A9: EMP1013 | B9: =LEN(Table2[[#This Row],[Employee ID]]) -> 7 | C9: Yuvraj Rout | D9: 29059 | E9: 36818 | F9: Sales | G9: 182803 | H9: Pune | I9: Male | J9: JC303 | K9: Lead | L9: 25
A10: EMP1014 | B10: =LEN(Table2[[#This Row],[Employee ID]]) -> 7 | C10: Anay Kothari | D10: 37619 | E10: 25882 | F10: Finance | G10: 127076 | H10: Pune | I10: Male | J10: JC710 | K10: Manager | L10: 55
A11: EMP1016 | B11: =LEN(Table2[[#This Row],[Employee ID]]) -> 7 | C11: Amani Manda | D11: 33969 | E11: 35916 | F11: Support | G11: 65259 | H11: Chennai | I11: Female | J11: JC991 | K11: Analyst | L11: 27
A12: EMP1017 | B12: =LEN(Table2[[#This Row],[Employee ID]]) -> 7 | C12: Azad Trivedi | D12: 28579 | E12: 43735 | F12: IT | G12: 178832 | H12: Ahmedabad | I12: Male | J12: JC944 | K12: Lead | L12: 6
A13: EMP1019 | B13: =LEN(Table2[[#This Row],[Employee ID]]) -> 7 | C13: Kaira Shukla | D13: 28684 | E13: 38675 | F13: IT | G13: 57911 | H13: Ahmedabad | I13: Female | J13: JC767 | K13: Manager | L13: 20
... A1298: EMP2892 | B1298: =LEN(Table2[[#This Row],[Employee ID]]) -> 7 | C1298: Yashvi Bail | D1298: 35607 | E1298: 36415 | F1298: Sales | G1298: 132701 | H1298: Hyderabad | I1298: Male | J1298: JC713 | K1298: Consultant | L1298: 26

Sheet aggregation funcation
B5: SUMIFS | H5: COUNTIFS
B7: LOCATION | C7: SALAERY | G7: LOCATION | H7: Department | I7: Gender | J7: EMPLOYEES WORKING
B8: Kolkata | C8: =SUMIFS(Table2[Salary],Table2[Location],'aggregation funcation'!B8) -> 15381678 | G8: Kolkata | H8: Marketing | I8: Female | J8: =COUNTIFS(Table2[[#All],[Location]],'aggregation funcation'!G8,Table2[[#All],[Department]],'aggregation funcation'!H8,Table2[[#All],[Gender]],'aggregation funcation'!I8) -> 16
B9: Mumbai | C9: =SUMIFS(Table2[Salary],Table2[Location],'aggregation funcation'!B9) -> 16103767 | G9: Mumbai | H9: Support | I9: Male | J9: =COUNTIFS(Table2[[#All],[Location]],'aggregation funcation'!G9,Table2[[#All],[Department]],'aggregation funcation'!H9,Table2[[#All],[Gender]],'aggregation funcation'!I9) -> 7
B10: Ahmedabad | C10: =SUMIFS(Table2[Salary],Table2[Location],'aggregation funcation'!B10) -> 14961932 | G10: Ahmedabad | H10: Operations | I10: Female | J10: =COUNTIFS(Table2[[#All],[Location]],'aggregation funcation'!G10,Table2[[#All],[Department]],'aggregation funcation'!H10,Table2[[#All],[Gender]],'aggregation funcation'!I10) -> 12
B11: Chennai | C11: =SUMIFS(Table2[Salary],Table2[Location],'aggregation funcation'!B11) -> 13751738 | G11: Chennai | H11: HR | I11: Male | J11: =COUNTIFS(Table2[[#All],[Location]],'aggregation funcation'!G11,Table2[[#All],[Department]],'aggregation funcation'!H11,Table2[[#All],[Gender]],'aggregation funcation'!I11) -> 7
B12: Delhi | C12: =SUMIFS(Table2[Salary],Table2[Location],'aggregation funcation'!B12) -> 16785158 | G12: Delhi | H12: IT | I12: Male | J12: =COUNTIFS(Table2[[#All],[Location]],'aggregation funcation'!G12,Table2[[#All],[Department]],'aggregation funcation'!H12,Table2[[#All],[Gender]],'aggregation funcation'!I12) -> 9
B13: Pune | C13: =SUMIFS(Table2[Salary],Table2[Location],'aggregation funcation'!B13) -> 13445146 | G13: Pune | H13: HR | I13: Male | J13: =COUNTIFS(Table2[[#All],[Location]],'aggregation funcation'!G13,Table2[[#All],[Department]],'aggregation funcation'!H13,Table2[[#All],[Gender]],'aggregation funcation'!I13) -> 10
B14: Jaipur | C14: =SUMIFS(Table2[Salary],Table2[Location],'aggregation funcation'!B14) -> 14363742 | G14: Jaipur | H14: Finance | I14: Female | J14: =COUNTIFS(Table2[[#All],[Location]],'aggregation funcation'!G14,Table2[[#All],[Department]],'aggregation funcation'!H14,Table2[[#All],[Gender]],'aggregation funcation'!I14) -> 9
B15: Hyderabad | C15: =SUMIFS(Table2[Salary],Table2[Location],'aggregation funcation'!B15) -> 15276042 | G15: Hyderabad | H15: Support | I15: Male | J15: =COUNTIFS(Table2[[#All],[Location]],'aggregation funcation'!G15,Table2[[#All],[Department]],'aggregation funcation'!H15,Table2[[#All],[Gender]],'aggregation funcation'!I15) -> 7
B16: Lucknow | C16: =SUMIFS(Table2[Salary],Table2[Location],'aggregation funcation'!B16) -> 12085163 | G16: Lucknow | H16: Sales | I16: Male | J16: =COUNTIFS(Table2[[#All],[Location]],'aggregation funcation'!G16,Table2[[#All],[Department]],'aggregation funcation'!H16,Table2[[#All],[Gender]],'aggregation funcation'!I16) -> 5
B17: Bangalore | C17: =SUMIFS(Table2[Salary],Table2[Location],'aggregation funcation'!B17) -> 15825924 | G17: Bangalore | H17: IT | I17: Female | J17: =COUNTIFS(Table2[[#All],[Location]],'aggregation funcation'!G17,Table2[[#All],[Department]],'aggregation funcation'!H17,Table2[[#All],[Gender]],'aggregation funcation'!I17) -> 6

Sheet reference funcation
E6: VLOOKUP
D8: Employee ID | E8: Employee NAME | F8: GENDER | G8: DEPARTMENT | H8: LOCATION | N8: XLOOKUP
D9: EMP2123 | E9: =VLOOKUP( 'reference funcation'!D9,'row data'!A1:K1300,2,0) -> Lakshit Bandi | F9: =VLOOKUP(D9,'row data'!$A$1:$K$1300,8,0) -> Female | G9: =VLOOKUP( 'reference funcation'!D9,'row data'!A1:K1300,5,0) -> Finance | H9: =VLOOKUP( 'reference funcation'!D9,'row data'!A1:K1300,7,0) -> Kolkata
D10: EMP1512 | E10: =VLOOKUP( 'reference funcation'!D10,'row data'!A2:K1301,2,0) -> Yasmin Khatri | F10: =VLOOKUP(D10,'row data'!$A$1:$K$1300,8,0) -> Male | G10: =VLOOKUP( 'reference funcation'!D10,'row data'!A2:K1301,5,0) -> Support | H10: =VLOOKUP( 'reference funcation'!D10,'row data'!A2:K1301,7,0) -> Jaipur
D11: EMP2189 | E11: =VLOOKUP( 'reference funcation'!D11,'row data'!A3:K1302,2,0) -> Riaan Grover | F11: =VLOOKUP(D11,'row data'!$A$1:$K$1300,8,0) -> Male | G11: =VLOOKUP( 'reference funcation'!D11,'row data'!A3:K1302,5,0) -> Marketing | H11: =VLOOKUP( 'reference funcation'!D11,'row data'!A3:K1302,7,0) -> Chennai | M11: Employee Name | N11: Anay Kothari | O11: Romil Saha
D12: EMP1522 | E12: =VLOOKUP( 'reference funcation'!D12,'row data'!A4:K1303,2,0) -> Anya Samra | F12: =VLOOKUP(D12,'row data'!$A$1:$K$1300,8,0) -> Male | G12: =VLOOKUP( 'reference funcation'!D12,'row data'!A4:K1303,5,0) -> HR | H12: =VLOOKUP( 'reference funcation'!D12,'row data'!A4:K1303,7,0) -> Chennai | M12: Department | N12: {=_xlfn.XLOOKUP('reference funcation'!N11,Table2[[#All],[Employee Name]],Table2[[#All],[Department]],)} -> Finance | O12: {=_xlfn.XLOOKUP('reference funcation'!O11,Table2[[#All],[Employee Name]],Table2[[#All],[Department]])} -> Sales
D13: EMP1151 | E13: =VLOOKUP( 'reference funcation'!D13,'row data'!A5:K1304,2,0) -> Riya Rajan | F13: =VLOOKUP(D13,'row data'!$A$1:$K$1300,8,0) -> Female | G13: =VLOOKUP( 'reference funcation'!D13,'row data'!A5:K1304,5,0) -> IT | H13: =VLOOKUP( 'reference funcation'!D13,'row data'!A5:K1304,7,0) -> Bangalore
D14: EMP1024 | E14: =VLOOKUP( 'reference funcation'!D14,'row data'!A6:K1305,2,0) -> Hrishita Sachar | F14: =VLOOKUP(D14,'row data'!$A$1:$K$1300,8,0) -> Male | G14: =VLOOKUP( 'reference funcation'!D14,'row data'!A6:K1305,5,0) -> Support | H14: =VLOOKUP( 'reference funcation'!D14,'row data'!A6:K1305,7,0) -> Delhi
D15: EMP2178 | E15: =VLOOKUP( 'reference funcation'!D15,'row data'!A7:K1306,2,0) -> Dharmajan Mander | F15: =VLOOKUP(D15,'row data'!$A$1:$K$1300,8,0) -> Male | G15: =VLOOKUP( 'reference funcation'!D15,'row data'!A7:K1306,5,0) -> Support | H15: =VLOOKUP( 'reference funcation'!D15,'row data'!A7:K1306,7,0) -> Ahmedabad
D16: EMP1965 | E16: =VLOOKUP( 'reference funcation'!D16,'row data'!A8:K1307,2,0) -> Tarini Chaudhry | F16: =VLOOKUP(D16,'row data'!$A$1:$K$1300,8,0) -> Male | G16: =VLOOKUP( 'reference funcation'!D16,'row data'!A8:K1307,5,0) -> HR | H16: =VLOOKUP( 'reference funcation'!D16,'row data'!A8:K1307,7,0) -> Mumbai
D17: EMP1256 | E17: =VLOOKUP( 'reference funcation'!D17,'row data'!A9:K1308,2,0) -> Adira Aggarwal | F17: =VLOOKUP(D17,'row data'!$A$1:$K$1300,8,0) -> Female | G17: =VLOOKUP( 'reference funcation'!D17,'row data'!A9:K1308,5,0) -> Finance | H17: =VLOOKUP( 'reference funcation'!D17,'row data'!A9:K1308,7,0) -> Pune

Sheet pivot table
A4: GENDER WISE EMPLOYEE COUNT BY DESIGNATION IN PERCENTAGE FORMATE
A5: Count of Location | B5: Column Labels
A6: Row Labels | B6: Female | C6: Male | D6: Grand Total
A7: Analyst | B7: 0.069390902 | C7: 0.077101002 | D7: 0.1464919
A8: Assistant | B8: 0.087124133 | C8: 0.063222822 | D8: 0.15034695
A9: Consultant | B9: 0.063993832 | C9: 0.067848882 | D9: 0.13184271
A10: Engineer | B10: 0.069390902 | C10: 0.074016962 | D10: 0.14340786
A11: Executive | B11: 0.060138782 | C11: 0.077872012 | D11: 0.13801079
A12: Lead | B12: 0.083269082 | C12: 0.067077872 | D12: 0.15034695
A13: Manager | B13: 0.067848882 | C13: 0.071703932 | D13: 0.13955281
A14: Grand Total | B14: 0.50115652 | C14: 0.49884348 | D14: 1
A17: EMPLOYEE DISTRIBUTION BY LOCATION
A18: Count of Department | B18: Column Labels
A19: Row Labels | B19: Analyst | C19: Assistant | D19: Consultant | E19: Engineer | F19: Executive | G19: Lead | H19: Manager | I19: Grand Total
A20: Ahmedabad | B20: 25 | C20: 17 | D20: 17 | E20: 21 | F20: 17 | G20: 26 | H20: 17 | I20: 140
A21: Bangalore | B21: 17 | C21: 13 | D21: 25 | E21: 14 | F21: 21 | G21: 17 | H21: 24 | I21: 131
A22: Chennai | B22: 16 | C22: 16 | D22: 12 | E22: 18 | F22: 19 | G22: 17 | H22: 24 | I22: 122
A23: Delhi | B23: 15 | C23: 23 | D23: 18 | E23: 20 | F23: 25 | G23: 22 | H23: 17 | I23: 140
A24: Hyderabad | B24: 17 | C24: 18 | D24: 21 | E24: 22 | F24: 17 | G24: 24 | H24: 10 | I24: 129
A25: Jaipur | B25: 19 | C25: 17 | D25: 12 | E25: 17 | F25: 20 | G25: 17 | H25: 22 | I25: 124
A26: Kolkata | B26: 28 | C26: 18 | D26: 22 | E26: 14 | F26: 16 | G26: 20 | H26: 15 | I26: 133
A27: Lucknow | B27: 16 | C27: 22 | D27: 17 | E27: 24 | F27: 12 | G27: 12 | H27: 12 | I27: 115
A28: Mumbai | B28: 21 | C28: 28 | D28: 17 | E28: 19 | F28: 16 | G28: 20 | H28: 18 | I28: 139
A29: Pune | B29: 16 | C29: 23 | D29: 10 | E29: 17 | F29: 16 | G29: 20 | H29: 22 | I29: 124
A30: Grand Total | B30: 190 | C30: 195 | D30: 171 | E30: 186 | F30: 179 | G30: 195 | H30: 181 | I30: 1297
A33: TOTAL WORKING EXPERIENCE BY DEPARTMENT AND GENDER
A34: Sum of Working Experience | B34: Column Labels
A35: Row Labels | B35: Finance | C35: HR | D35: IT | E35: Marketing | F35: Operations | G35: Sales | H35: Support | I35: Grand Total
A36: Female | B36: 2963 | C36: 3062 | D36: 2490 | E36: 2805 | F36: 3025 | G36: 2286 | H36: 2606 | I36: 19237
A37: Male | B37: 3252 | C37: 2310 | D37: 2330 | E37: 2624 | F37: 2668 | G37: 2876 | H37: 2516 | I37: 18576
A38: Grand Total | B38: 6215 | C38: 5372 | D38: 4820 | E38: 5429 | F38: 5693 | G38: 5162 | H38: 5122 | I38: 37813
A42: GENDER -WISE EMPLOYEE COUNT BY LOCATION
A43: Count of Job Code | B43: Column Labels
A44: Row Labels | B44: Female | C44: Male | D44: Grand Total
A45: Ahmedabad | B45: 69 | C45: 71 | D45: 140
A46: Bangalore | B46: 53 | C46: 78 | D46: 131
A47: Chennai | B47: 59 | C47: 63 | D47: 122
A48: Delhi | B48: 78 | C48: 62 | D48: 140
A49: Hyderabad | B49: 56 | C49: 73 | D49: 129
A50: Jaipur | B50: 70 | C50: 54 | D50: 124
...

Sheet dashboard
